<?xml version="1.0" encoding="UTF-8"?>
<!-- Generated by org.testng.reporters.JUnitXMLReporter -->
<testsuite ignored="0" hostname="HIJ-LP410" failures="2" tests="9" name="ReExeuction Of Failed TCs in TestNG" time="0.083" errors="0" timestamp="2021-02-27T21:01:02 IST">
  <testcase classname="test.ReTryTest" name="test1" time="0.011">
    <skipped/>
  </testcase> <!-- test1 -->
  <testcase classname="test.ReTryTest" name="test1" time="0.002">
    <skipped/>
  </testcase> <!-- test1 -->
  <testcase classname="test.ReTryTest" name="test1" time="0.001">
    <skipped/>
  </testcase> <!-- test1 -->
  <testcase classname="test.ReTryTest" name="test1" time="0.001">
    <failure type="java.lang.AssertionError" message="expected [false] but found [true]">
      <![CDATA[java.lang.AssertionError: expected [false] but found [true]
at test.ReTryTest.test1(ReTryTest.java:17)
at java.base/java.util.ArrayList.forEach(ArrayList.java:1511)
... Removed 33 stack frames]]>
    </failure>
  </testcase> <!-- test1 -->
  <testcase classname="test.ReTryTest" name="test2" time="0.001">
    <skipped/>
  </testcase> <!-- test2 -->
  <testcase classname="test.ReTryTest" name="test2" time="0.001">
    <skipped/>
  </testcase> <!-- test2 -->
  <testcase classname="test.ReTryTest" name="test2" time="0.001">
    <skipped/>
  </testcase> <!-- test2 -->
  <testcase classname="test.ReTryTest" name="test2" time="0.001">
    <failure type="java.lang.AssertionError" message="expected [false] but found [true]">
      <![CDATA[java.lang.AssertionError: expected [false] but found [true]
at test.ReTryTest.test2(ReTryTest.java:23)
at java.base/java.util.ArrayList.forEach(ArrayList.java:1511)
... Removed 33 stack frames]]>
    </failure>
  </testcase> <!-- test2 -->
  <testcase classname="test.ReTryTest" name="test3" time="0.001"/>
</testsuite> <!-- ReExeuction Of Failed TCs in TestNG -->
